<?xml version="1.0" ?>
<sdf version="1.8">
  <world name="ethiopia_cities">
    
    <!-- Physics -->
    <physics name="1ms" type="ode">
      <max_step_size>0.001</max_step_size>
      <real_time_factor>1.0</real_time_factor>
    </physics>
    
    <!-- Plugins for ROS2 integration -->
    <plugin filename="gz-sim-physics-system" name="gz::sim::systems::Physics"/>
    <plugin filename="gz-sim-user-commands-system" name="gz::sim::systems::UserCommands"/>
    <plugin filename="gz-sim-scene-broadcaster-system" name="gz::sim::systems::SceneBroadcaster"/>
    <plugin filename="gz-sim-sensors-system" name="gz::sim::systems::Sensors">
      <render_engine>ogre2</render_engine>
    </plugin>
    
    <!-- Scene -->
    <scene>
      <ambient>0.4 0.4 0.4 1</ambient>
      <background>0.7 0.85 1.0 1</background>
      <shadows>true</shadows>
    </scene>
    
    <!-- Sun Light -->
    <light type="directional" name="sun">
      <cast_shadows>true</cast_shadows>
      <pose>0 0 100 0 0 0</pose>
      <diffuse>0.8 0.8 0.8 1</diffuse>
      <specular>0.2 0.2 0.2 1</specular>
      <attenuation>
        <range>1000</range>
        <constant>0.9</constant>
        <linear>0.01</linear>
        <quadratic>0.001</quadratic>
      </attenuation>
      <direction>-0.5 0.1 -0.9</direction>
    </light>
    
    <!-- Ground Plane -->
    <model name="ground_plane">
      <static>true</static>
      <link name="link">
        <collision name="collision">
          <geometry>
            <plane>
              <normal>0 0 1</normal>
              <size>200 200</size>
            </plane>
          </geometry>
        </collision>
        <visual name="visual">
          <geometry>
            <plane>
              <normal>0 0 1</normal>
              <size>200 200</size>
            </plane>
          </geometry>
          <material>
            <ambient>0.3 0.5 0.2 1</ambient>
            <diffuse>0.3 0.5 0.2 1</diffuse>
          </material>
        </visual>
      </link>
    </model>
    
    <!-- ==================== ETHIOPIAN CITIES ==================== -->
    
    <!-- Addis Ababa (Capital - Origin) - GREEN -->
    <model name="addis_ababa">
      <static>true</static>
      <pose>0 0 0.5 0 0 0</pose>
      <link name="link">
        <visual name="marker">
          <geometry>
            <cylinder>
              <radius>1.5</radius>
              <length>1.0</length>
            </cylinder>
          </geometry>
          <material>
            <ambient>0.0 0.8 0.0 1</ambient>
            <diffuse>0.0 1.0 0.0 1</diffuse>
          </material>
        </visual>
        <visual name="label">
          <pose>0 0 1.2 0 0 0</pose>
          <geometry>
            <box>
              <size>4.0 0.5 0.5</size>
            </box>
          </geometry>
          <material>
            <ambient>1.0 1.0 1.0 1</ambient>
            <diffuse>1.0 1.0 1.0 1</diffuse>
          </material>
        </visual>
      </link>
    </model>
    
    <!-- Ambo - BLUE -->
    <model name="ambo">
      <static>true</static>
      <pose>-11 3 0.4 0 0 0</pose>
      <link name="link">
        <visual name="marker">
          <geometry>
            <cylinder>
              <radius>1.0</radius>
              <length>0.8</length>
            </cylinder>
          </geometry>
          <material>
            <ambient>0.0 0.4 0.8 1</ambient>
            <diffuse>0.0 0.5 1.0 1</diffuse>
          </material>
        </visual>
      </link>
    </model>
    
    <!-- Jimma - ORANGE (Coffee region) -->
    <model name="jimma">
      <static>true</static>
      <pose>-25 -15 0.4 0 0 0</pose>
      <link name="link">
        <visual name="marker">
          <geometry>
            <cylinder>
              <radius>1.2</radius>
              <length>0.8</length>
            </cylinder>
          </geometry>
          <material>
            <ambient>0.8 0.4 0.0 1</ambient>
            <diffuse>1.0 0.5 0.0 1</diffuse>
          </material>
        </visual>
      </link>
    </model>
    
    <!-- Wolaita Sodo - BLUE -->
    <model name="wolaita_sodo">
      <static>true</static>
      <pose>-20 -30 0.4 0 0 0</pose>
      <link name="link">
        <visual name="marker">
          <geometry>
            <cylinder>
              <radius>1.0</radius>
              <length>0.8</length>
            </cylinder>
          </geometry>
          <material>
            <ambient>0.0 0.4 0.8 1</ambient>
            <diffuse>0.0 0.5 1.0 1</diffuse>
          </material>
        </visual>
      </link>
    </model>
    
    <!-- Arba Minch - BLUE -->
    <model name="arba_minch">
      <static>true</static>
      <pose>-15 -45 0.4 0 0 0</pose>
      <link name="link">
        <visual name="marker">
          <geometry>
            <cylinder>
              <radius>1.0</radius>
              <length>0.8</length>
            </cylinder>
          </geometry>
          <material>
            <ambient>0.0 0.4 0.8 1</ambient>
            <diffuse>0.0 0.5 1.0 1</diffuse>
          </material>
        </visual>
      </link>
    </model>
    
    <!-- Konso - BLUE -->
    <model name="konso">
      <static>true</static>
      <pose>-5 -55 0.4 0 0 0</pose>
      <link name="link">
        <visual name="marker">
          <geometry>
            <cylinder>
              <radius>0.8</radius>
              <length>0.8</length>
            </cylinder>
          </geometry>
          <material>
            <ambient>0.0 0.4 0.8 1</ambient>
            <diffuse>0.0 0.5 1.0 1</diffuse>
          </material>
        </visual>
      </link>
    </model>
    
    <!-- Moyale - RED (Goal) -->
    <model name="moyale">
      <static>true</static>
      <pose>5 -70 0.4 0 0 0</pose>
      <link name="link">
        <visual name="marker">
          <geometry>
            <cylinder>
              <radius>1.2</radius>
              <length>0.8</length>
            </cylinder>
          </geometry>
          <material>
            <ambient>0.8 0.0 0.0 1</ambient>
            <diffuse>1.0 0.0 0.0 1</diffuse>
          </material>
        </visual>
      </link>
    </model>
    
    <!-- Adama - BLUE -->
    <model name="adama">
      <static>true</static>
      <pose>10 -2 0.4 0 0 0</pose>
      <link name="link">
        <visual name="marker">
          <geometry>
            <cylinder>
              <radius>1.0</radius>
              <length>0.8</length>
            </cylinder>
          </geometry>
          <material>
            <ambient>0.0 0.4 0.8 1</ambient>
            <diffuse>0.0 0.5 1.0 1</diffuse>
          </material>
        </visual>
      </link>
    </model>
    
    <!-- Dire Dawa - BLUE -->
    <model name="dire_dawa">
      <static>true</static>
      <pose>35 5 0.4 0 0 0</pose>
      <link name="link">
        <visual name="marker">
          <geometry>
            <cylinder>
              <radius>1.0</radius>
              <length>0.8</length>
            </cylinder>
          </geometry>
          <material>
            <ambient>0.0 0.4 0.8 1</ambient>
            <diffuse>0.0 0.5 1.0 1</diffuse>
          </material>
        </visual>
      </link>
    </model>
    
    <!-- Harar - ORANGE (Coffee region) -->
    <model name="harar">
      <static>true</static>
      <pose>40 8 0.4 0 0 0</pose>
      <link name="link">
        <visual name="marker">
          <geometry>
            <cylinder>
              <radius>1.0</radius>
              <length>0.8</length>
            </cylinder>
          </geometry>
          <material>
            <ambient>0.8 0.4 0.0 1</ambient>
            <diffuse>1.0 0.5 0.0 1</diffuse>
          </material>
        </visual>
      </link>
    </model>
    
    <!-- Debre Berhan - BLUE -->
    <model name="debre_berhan">
      <static>true</static>
      <pose>5 13 0.4 0 0 0</pose>
      <link name="link">
        <visual name="marker">
          <geometry>
            <cylinder>
              <radius>0.8</radius>
              <length>0.8</length>
            </cylinder>
          </geometry>
          <material>
            <ambient>0.0 0.4 0.8 1</ambient>
            <diffuse>0.0 0.5 1.0 1</diffuse>
          </material>
        </visual>
      </link>
    </model>
    
    <!-- Dessie - BLUE -->
    <model name="dessie">
      <static>true</static>
      <pose>8 30 0.4 0 0 0</pose>
      <link name="link">
        <visual name="marker">
          <geometry>
            <cylinder>
              <radius>1.0</radius>
              <length>0.8</length>
            </cylinder>
          </geometry>
          <material>
            <ambient>0.0 0.4 0.8 1</ambient>
            <diffuse>0.0 0.5 1.0 1</diffuse>
          </material>
        </visual>
      </link>
    </model>
    
    <!-- Lalibela - GOLD (Historical) -->
    <model name="lalibela">
      <static>true</static>
      <pose>-5 45 0.4 0 0 0</pose>
      <link name="link">
        <visual name="marker">
          <geometry>
            <cylinder>
              <radius>1.2</radius>
              <length>0.8</length>
            </cylinder>
          </geometry>
          <material>
            <ambient>0.8 0.6 0.0 1</ambient>
            <diffuse>1.0 0.8 0.0 1</diffuse>
          </material>
        </visual>
      </link>
    </model>
    
    <!-- Bahir Dar - CYAN (Lake Tana) -->
    <model name="bahir_dar">
      <static>true</static>
      <pose>-30 35 0.4 0 0 0</pose>
      <link name="link">
        <visual name="marker">
          <geometry>
            <cylinder>
              <radius>1.2</radius>
              <length>0.8</length>
            </cylinder>
          </geometry>
          <material>
            <ambient>0.0 0.6 0.8 1</ambient>
            <diffuse>0.0 0.8 1.0 1</diffuse>
          </material>
        </visual>
      </link>
    </model>
    
    <!-- Gondar - GOLD (Historical) -->
    <model name="gondar">
      <static>true</static>
      <pose>-35 50 0.4 0 0 0</pose>
      <link name="link">
        <visual name="marker">
          <geometry>
            <cylinder>
              <radius>1.2</radius>
              <length>0.8</length>
            </cylinder>
          </geometry>
          <material>
            <ambient>0.8 0.6 0.0 1</ambient>
            <diffuse>1.0 0.8 0.0 1</diffuse>
          </material>
        </visual>
      </link>
    </model>
    
    <!-- Axum - GOLD (Historical) -->
    <model name="axum">
      <static>true</static>
      <pose>-20 70 0.4 0 0 0</pose>
      <link name="link">
        <visual name="marker">
          <geometry>
            <cylinder>
              <radius>1.3</radius>
              <length>0.8</length>
            </cylinder>
          </geometry>
          <material>
            <ambient>0.8 0.6 0.0 1</ambient>
            <diffuse>1.0 0.8 0.0 1</diffuse>
          </material>
        </visual>
      </link>
    </model>
    
    <!-- Mekelle - BLUE -->
    <model name="mekelle">
      <static>true</static>
      <pose>15 55 0.4 0 0 0</pose>
      <link name="link">
        <visual name="marker">
          <geometry>
            <cylinder>
              <radius>1.2</radius>
              <length>0.8</length>
            </cylinder>
          </geometry>
          <material>
            <ambient>0.0 0.4 0.8 1</ambient>
            <diffuse>0.0 0.5 1.0 1</diffuse>
          </material>
        </visual>
      </link>
    </model>
    
    <!-- Debre Markos - BLUE -->
    <model name="debre_markos">
      <static>true</static>
      <pose>-20 15 0.4 0 0 0</pose>
      <link name="link">
        <visual name="marker">
          <geometry>
            <cylinder>
              <radius>0.9</radius>
              <length>0.8</length>
            </cylinder>
          </geometry>
          <material>
            <ambient>0.0 0.4 0.8 1</ambient>
            <diffuse>0.0 0.5 1.0 1</diffuse>
          </material>
        </visual>
      </link>
    </model>

    <!-- ==================== THREE-WHEEL ROBOT ==================== -->
    <model name="traveling_robot">
      <pose>0 0 0.1 0 0 0</pose>
      
      <!-- Chassis -->
      <link name="chassis">
        <pose>0 0 0.075 0 0 0</pose>
        <inertial>
          <mass>5.0</mass>
          <inertia>
            <ixx>0.0417</ixx>
            <iyy>0.0717</iyy>
            <izz>0.1042</izz>
          </inertia>
        </inertial>
        <collision name="collision">
          <geometry>
            <box>
              <size>0.4 0.3 0.1</size>
            </box>
          </geometry>
        </collision>
        <visual name="visual">
          <geometry>
            <box>
              <size>0.4 0.3 0.1</size>
            </box>
          </geometry>
          <material>
            <ambient>0.0 0.5 0.0 1</ambient>
            <diffuse>0.0 0.8 0.0 1</diffuse>
          </material>
        </visual>
      </link>
      
      <!-- Left Wheel -->
      <link name="left_wheel">
        <pose>-0.1 0.17 0.075 -1.5707 0 0</pose>
        <inertial>
          <mass>0.5</mass>
          <inertia>
            <ixx>0.0007</ixx>
            <iyy>0.0007</iyy>
            <izz>0.0014</izz>
          </inertia>
        </inertial>
        <collision name="collision">
          <geometry>
            <cylinder>
              <radius>0.075</radius>
              <length>0.04</length>
            </cylinder>
          </geometry>
          <surface>
            <friction>
              <ode>
                <mu>1.0</mu>
                <mu2>1.0</mu2>
              </ode>
            </friction>
          </surface>
        </collision>
        <visual name="visual">
          <geometry>
            <cylinder>
              <radius>0.075</radius>
              <length>0.04</length>
            </cylinder>
          </geometry>
          <material>
            <ambient>0.1 0.1 0.1 1</ambient>
            <diffuse>0.2 0.2 0.2 1</diffuse>
          </material>
        </visual>
      </link>
      
      <!-- Right Wheel -->
      <link name="right_wheel">
        <pose>-0.1 -0.17 0.075 -1.5707 0 0</pose>
        <inertial>
          <mass>0.5</mass>
          <inertia>
            <ixx>0.0007</ixx>
            <iyy>0.0007</iyy>
            <izz>0.0014</izz>
          </inertia>
        </inertial>
        <collision name="collision">
          <geometry>
            <cylinder>
              <radius>0.075</radius>
              <length>0.04</length>
            </cylinder>
          </geometry>
          <surface>
            <friction>
              <ode>
                <mu>1.0</mu>
                <mu2>1.0</mu2>
              </ode>
            </friction>
          </surface>
        </collision>
        <visual name="visual">
          <geometry>
            <cylinder>
              <radius>0.075</radius>
              <length>0.04</length>
            </cylinder>
          </geometry>
          <material>
            <ambient>0.1 0.1 0.1 1</ambient>
            <diffuse>0.2 0.2 0.2 1</diffuse>
          </material>
        </visual>
      </link>
      
      <!-- Caster Wheel -->
      <link name="caster">
        <pose>0.13 0 0.04 0 0 0</pose>
        <inertial>
          <mass>0.2</mass>
          <inertia>
            <ixx>0.00013</ixx>
            <iyy>0.00013</iyy>
            <izz>0.00013</izz>
          </inertia>
        </inertial>
        <collision name="collision">
          <geometry>
            <sphere>
              <radius>0.04</radius>
            </sphere>
          </geometry>
          <surface>
            <friction>
              <ode>
                <mu>0.0</mu>
                <mu2>0.0</mu2>
              </ode>
            </friction>
          </surface>
        </collision>
        <visual name="visual">
          <geometry>
            <sphere>
              <radius>0.04</radius>
            </sphere>
          </geometry>
          <material>
            <ambient>0.5 0.5 0.5 1</ambient>
            <diffuse>0.7 0.7 0.7 1</diffuse>
          </material>
        </visual>
      </link>
      
      <!-- Lidar -->
      <link name="lidar_link">
        <pose>0.1 0 0.18 0 0 0</pose>
        <inertial>
          <mass>0.1</mass>
          <inertia>
            <ixx>0.00002</ixx>
            <iyy>0.00002</iyy>
            <izz>0.00002</izz>
          </inertia>
        </inertial>
        <visual name="visual">
          <geometry>
            <cylinder>
              <radius>0.03</radius>
              <length>0.04</length>
            </cylinder>
          </geometry>
          <material>
            <ambient>0.8 0.0 0.0 1</ambient>
            <diffuse>1.0 0.0 0.0 1</diffuse>
          </material>
        </visual>
        <sensor name="lidar" type="gpu_lidar">
          <always_on>true</always_on>
          <update_rate>10</update_rate>
          <lidar>
            <scan>
              <horizontal>
                <samples>360</samples>
                <resolution>1</resolution>
                <min_angle>-3.14159</min_angle>
                <max_angle>3.14159</max_angle>
              </horizontal>
            </scan>
            <range>
              <min>0.1</min>
              <max>30.0</max>
              <resolution>0.01</resolution>
            </range>
          </lidar>
          <visualize>true</visualize>
        </sensor>
      </link>
      
      <!-- IMU -->
      <link name="imu_link">
        <pose>0 0 0.14 0 0 0</pose>
        <inertial>
          <mass>0.01</mass>
          <inertia>
            <ixx>0.000001</ixx>
            <iyy>0.000001</iyy>
            <izz>0.000001</izz>
          </inertia>
        </inertial>
        <visual name="visual">
          <geometry>
            <box>
              <size>0.02 0.02 0.02</size>
            </box>
          </geometry>
          <material>
            <ambient>1.0 1.0 0.0 1</ambient>
            <diffuse>1.0 1.0 0.0 1</diffuse>
          </material>
        </visual>
        <sensor name="imu" type="imu">
          <always_on>true</always_on>
          <update_rate>100</update_rate>
        </sensor>
      </link>
      
      <!-- Joints -->
      <joint name="left_wheel_joint" type="revolute">
        <parent>chassis</parent>
        <child>left_wheel</child>
        <axis>
          <xyz>0 0 1</xyz>
        </axis>
      </joint>
      
      <joint name="right_wheel_joint" type="revolute">
        <parent>chassis</parent>
        <child>right_wheel</child>
        <axis>
          <xyz>0 0 1</xyz>
        </axis>
      </joint>
      
      <joint name="caster_joint" type="fixed">
        <parent>chassis</parent>
        <child>caster</child>
      </joint>
      
      <joint name="lidar_joint" type="fixed">
        <parent>chassis</parent>
        <child>lidar_link</child>
      </joint>
      
      <joint name="imu_joint" type="fixed">
        <parent>chassis</parent>
        <child>imu_link</child>
      </joint>
      
      <!-- Differential Drive Plugin -->
      <plugin filename="gz-sim-diff-drive-system" name="gz::sim::systems::DiffDrive">
        <left_joint>left_wheel_joint</left_joint>
        <right_joint>right_wheel_joint</right_joint>
        <wheel_separation>0.34</wheel_separation>
        <wheel_radius>0.075</wheel_radius>
        <max_linear_acceleration>2</max_linear_acceleration>
        <min_linear_acceleration>-2</min_linear_acceleration>
        <max_angular_acceleration>3</max_angular_acceleration>
        <min_angular_acceleration>-3</min_angular_acceleration>
        <topic>/cmd_vel</topic>
        <odom_topic>/odom</odom_topic>
        <tf_topic>/tf</tf_topic>
        <frame_id>odom</frame_id>
        <child_frame_id>chassis</child_frame_id>
        <odom_publish_frequency>50</odom_publish_frequency>
      </plugin>
      
    </model>

  </world>
</sdf>

